Workbook

Sheet Snapshot
A2: TIG Weekly Financial Snapshot as of the 2nd of October 2025
A4: Description | C4: 45839 | D4: 45870 | E4: 45901 | F4: 45931 | G4: 45962 | H4: 45992 | I4: 46023 | J4: 46054 | K4: 46082 | L4: 46113 | M4: 46143 | N4: 46174 | O4: Total
A5: Monthly Shipped Sales
A6: HQ | C6: 1350599.8 | D6: 1039303.9 | E6: 1184140.2 | F6: 69196 | O6: =SUM(C6:N6) -> 3643239.9
C7: =C6/C13 -> 0.79884071 | D7: 0.833985 | E7: 0.83818736 | F7: =F6/F12 -> 0.84004273 | G7: =G6/#REF! -> #REF! | H7: =H6/#REF! -> #REF! | I7: =I6/#REF! -> #REF! | J7: =J6/#REF! -> #REF! | K7: =K6/#REF! -> #REF! | L7: =L6/#REF! -> #REF! | M7: =M6/#REF! -> #REF! | N7: =N6/#REF! -> #REF! | O7: =SUM(C7:N7) -> #REF!
A8: 3PL | C8: 340099.96 | D8: 198913.26 | E8: 76883 | F8: 12047 | O8: =SUM(C8:N8) -> 627943.22
C9: =C8/C13 -> 0.20115929 | D9: 0.1596171 | E9: 0.053744379 | F9: =F8/F12 -> 0.14625115
A10: NZ | C10: 0 | D10: 7973 | E10: 154595 | F10: 1129 | O10: =SUM(C10:N10) -> 163697
C11: =C10/C14 -> 0 | D11: 0.0052893555 | E11: 0.10806826 | F11: =F10/F12 -> 0.013706114 | G11: =#REF!/G10 -> #REF! | H11: =#REF!/H10 -> #REF! | I11: =#REF!/I10 -> #REF! | J11: =#REF!/J10 -> #REF! | K11: =#REF!/K10 -> #REF! | L11: =#REF!/L10 -> #REF! | M11: =#REF!/M10 -> #REF! | N11: =#REF!/N10 -> #REF! | O11: =#REF!/O10 -> #REF!
A12: Shipped Sales Total | C12: Shipped | D12: Shipped | E12: Shipped | F12: =SUM(F10+F8+F6) -> 82372
A13: Invoiced Sales Total | C13: 1690699.7 | D13: 1246190.1 | E13: 1415618.2 | F13: 4553 | G13: ='25-26 Budget-Actual Invoiced'!I229 -> 0 | H13: ='25-26 Budget-Actual Invoiced'!J229 -> 0 | I13: ='25-26 Budget-Actual Invoiced'!K229 -> 0 | J13: ='25-26 Budget-Actual Invoiced'!L229 -> 0 | K13: ='25-26 Budget-Actual Invoiced'!M229 -> 0 | L13: ='25-26 Budget-Actual Invoiced'!N229 -> 0 | M13: ='25-26 Budget-Actual Invoiced'!O229 -> 0 | N13: ='25-26 Budget-Actual Invoiced'!P229 -> 0 | O13: =SUM(C13:N13) -> 4357061.1
A14: Budget | C14: 1435665 | D14: 1507367 | E14: 1732767 | F14: 1157167 | G14: 1168617 | H14: 1082167 | I14: 1077167 | J14: 1196667 | K14: 1630917 | L14: 1429367 | M14: 1255817 | N14: 1327815 | O14: =SUM(C14:N14) -> 16001500
A15: % of Budget | C15: =C13/C14 -> 1.1776422 | D15: =D13/D14 -> 0.82673306 | E15: =E13/E14 -> 0.81696976 | F15: =F12/F14 -> 0.071184194 | G15: =G12/G14 -> 0 | H15: =H12/H14 -> 0 | I15: =I12/I14 -> 0 | J15: =J12/J14 -> 0 | K15: =K12/K14 -> 0 | L15: =L12/L14 -> 0 | M15: =M12/M14 -> 0 | ... O15: =O12/O14 -> 0
A16: $ Variance | C16: =C13-C14 -> 255034.71 | D16: =D13-D14 -> -261176.87 | E16: =E13-E14 -> -317148.76 | F16: =F12-F14 -> -1074795 | G16: =G12-G14 -> -1168617 | H16: =H12-H14 -> -1082167 | I16: =I12-I14 -> -1077167 | J16: =J12-J14 -> -1196667 | K16: =K12-K14 -> -1630917 | L16: =L12-L14 -> -1429367 | M16: =M12-M14 -> -1255817 | N16: =N12-N14 -> -1327815 | O16: =SUM(C16:N16) -> -11566620
A17: % Variance | C17: =C16/C14 -> 0.17764221 | D17: =D16/D14 -> -0.17326694 | E17: =E16/E14 -> -0.18303024 | F17: =F16/F14 -> -0.92881581 | G17: =G16/G14 -> -1 | H17: =H16/H14 -> -1 | I17: =I16/I14 -> -1 | J17: =J16/J14 -> -1 | ... O17: =O16/O14 -> -0.72284598
A19: HQ WIP | B19: Order $ | C19: 0 | D19: 0 | E19: 0 | F19: 472033 | G19: 0 | H19: 0 | I19: 0 | J19: 0 | K19: 0 | L19: 0 | M19: 0 | N19: 0 | O19: =SUM(C19:N19) -> 472033
B20: Order QTY | C20: 0 | D20: 0 | E20: 0 | F20: 1444 | G20: 0 | H20: 0 | I20: 0 | J20: 0 | K20: 0 | L20: 0 | M20: 0 | N20: 0 | O20: =SUM(C20:N20) -> 1444
B21: B/O $ | C21: 0 | D21: 0 | E21: 0 | F21: 62795 | G21: 0 | H21: 0 | I21: 0 | J21: 0 | K21: 0 | L21: 0 | M21: 0 | N21: 0 | O21: =SUM(C21:N21) -> 62795
B22: B/O QTY | C22: 0 | D22: 0 | E22: 0 | F22: 352 | G22: 0 | H22: 0 | I22: 0 | J22: 0 | K22: 0 | L22: 0 | M22: 0 | N22: 0 | O22: =SUM(C22:N22) -> 352
B23: BOOKED $ | C23: 0 | D23: 0 | E23: 0 | F23: 104591 | G23: 0 | H23: 0 | I23: 0 | J23: 0 | K23: 0 | L23: 0 | M23: 0 | N23: 0 | O23: =SUM(C23:N23) -> 104591
B24: BOOKED QTY | C24: 0 | D24: 0 | E24: 0 | F24: 78 | G24: 0 | H24: 0 | I24: 0 | J24: 0 | K24: 0 | L24: 0 | M24: 0 | N24: 0 | O24: =SUM(C24:N24) -> 78
A25: 3PL WIP | B25: Order $ | C25: 0 | D25: 0 | E25: 0 | F25: 133492 | G25: 0 | H25: 0 | I25: 0 | J25: 0 | K25: 0 | L25: 0 | M25: 0 | N25: 0 | O25: =SUM(C25:N25) -> 133492
B26: Order QTY | C26: 0 | D26: 0 | E26: 0 | F26: 759 | G26: 0 | H26: 0 | I26: 0 | J26: 0 | K26: 0 | L26: 0 | M26: 0 | N26: 0 | O26: =SUM(C26:N26) -> 759
B27: B/O $ | C27: 0 | D27: 0 | E27: 0 | F27: 29677 | G27: 0 | H27: 0 | J27: 0 | K27: 0 | L27: 0 | M27: 0 | N27: 0 | O27: =SUM(C27:N27) -> 29677
B28: B/O QTY | C28: 0 | D28: 0 | E28: 0 | F28: 187 | G28: 0 | H28: 0 | J28: 0 | K28: 0 | L28: 0 | M28: 0 | N28: 0 | O28: =SUM(C28:N28) -> 187
A29: NZ WIP | B29: Order $ | C29: 0 | D29: 0 | E29: 0 | F29: 11473 | G29: 0 | H29: 0 | I29: 0 | J29: 0 | K29: 0 | L29: 0 | M29: 0 | N29: 0 | O29: =SUM(C29:N29) -> 11473
B30: Order QTY | C30: 0 | D30: 0 | E30: 0 | F30: 46 | G30: 0 | H30: 0 | I30: 0 | J30: 0 | K30: 0 | L30: 0 | M30: 0 | N30: 0 | O30: =SUM(C30:N30) -> 46
B31: B/O $ | C31: 0 | D31: 0 | E31: 0 | F31: 10827 | G31: 0 | H31: 0 | J31: 0 | K31: 0 | L31: 0 | M31: 0 | N31: 0 | O31: =SUM(C31:N31) -> 10827
B32: B/O QTY | C32: 0 | D32: 0 | E32: 0 | F32: 43 | G32: 0 | H32: 0 | J32: 0 | K32: 0 | L32: 0 | M32: 0 | N32: 0 | O32: =SUM(C32:N32) -> 43
A33: Total WIP | B33: Value | C33: =SUM(C27,C25,C23,C21,C19,C29,C31) -> 0 | D33: =SUM(D27,D25,D23,D21,D19,D29,D31) -> 0 | E33: =SUM(E27,E25,E23,E21,E19,E29,E31) -> 0 | F33: =SUM(F27,F25,F23,F21,F19,F29,F31) -> 824888 | G33: =SUM(G27,G25,G23,G21,G19,G29,G31) -> 0 | H33: =SUM(H27,H25,H23,H21,H19,H29,H31) -> 0 | I33: =SUM(I27,I25,I23,I21,I19,I29,I31) -> 0 | J33: =SUM(J27,J25,J23,J21,J19,J29,J31) -> 0 | ... N33: =SUM(N27,N25,N23,N21,N19,N29,N31) -> 0 | O33: =SUM(C33:N33) -> 824888
B34: Orders | C34: =SUM(C28,C26,C24,C22,C20,C30,C32) -> 0 | D34: =SUM(D28,D26,D24,D22,D20,D30,D32) -> 0 | E34: =SUM(E28,E26,E24,E22,E20,E30,E32) -> 0 | F34: =SUM(F28,F26,F24,F22,F20,F30,F32) -> 2909 | G34: =SUM(G28,G26,G24,G22,G20,G30,G32) -> 0 | H34: =SUM(H28,H26,H24,H22,H20,H30,H32) -> 0 | I34: =SUM(I28,I26,I24,I22,I20,I30,I32) -> 0 | J34: =SUM(J28,J26,J24,J22,J20,J30,J32) -> 0 | ... N34: =SUM(N28,N26,N24,N22,N20,N30,N32) -> 0 | O34: =SUM(C34:N34) -> 2909

Sheet 25-26 Budget-Actual Invoiced
A1: Sales Budget Vs Actual Invoiced- 1st July 2025 to 30 June 2026 | Q1: Annual | S1: % Of Sales
A2: Account Manager | B2: Non-Report | C2: Customer Name | E2: 45839 | F2: 45870 | G2: 45901 | H2: 45931 | I2: 45962 | J2: 45992 | K2: 46023 | L2: 46054 | M2: 46082 | N2: 46113 | O2: 46143 | P2: 46174 | Q2: Total | R2: % to Budget
A3: Ann | B3: C-Anchored | C3: WINNING APPLIANCES | D3: Actual | E3: 770 | F3: 7770.75 | G3: 5529.97 | Q3: =+SUM(E3:P3) -> 14070.72 | R3: =Q3/Q4 -> 0.25583127 | S3: 0
D4: Budget | E4: 3000 | F4: 4200 | G4: 1600 | H4: 7500 | I4: 5450 | J4: 1500 | K4: 4000 | L4: 4000 | M4: 7750 | N4: 6700 | O4: 4650 | P4: 4650 | Q4: =SUM(E4:P4) -> 55000 | S4: =Q4/$Q$230 -> 0.0034371778
A5: Ann | B5: C-Anchored | C5: HARVEY NORMAN | D5: Actual | E5: 179440.36 | F5: 138218.8 | G5: 37125.06 | Q5: =+SUM(E5:P5) -> 354784.22 | R5: =Q5/Q6 -> 0.32107169 | S5: 0
D6: Budget | E6: 105000 | F6: 100000 | G6: 75000 | H6: 75000 | I6: 100000 | J6: 100000 | K6: 80000 | L6: 80000 | M6: 95000 | N6: 95000 | O6: 100000 | P6: 100000 | Q6: =SUM(E6:P6) -> 1105000 | S6: =Q6/$Q$230 -> 0.069056026
A7: Ann | B7: C-Anchored | C7: HARVEY NORMAN NZ | D7: Actual | F7: 7973.4671 | G7: 154525.83 | Q7: =+SUM(E7:P7) -> 162499.29 | R7: =Q7/Q8 -> 0.44520354 | S7: 0
D8: Budget | G8: 220000 | H8: 20000 | I8: 20000 | J8: 15000 | K8: 15000 | L8: 15000 | M8: 15000 | N8: 15000 | O8: 15000 | P8: 15000 | Q8: =SUM(E8:P8) -> 365000 | S8: =Q8/$Q$230 -> 0.022810362
A9: Ann | B9: C-Anchored | C9: Aus Nursing Home (NHF) | D9: Actual | E9: 2856 | F9: 3702 | G9: 9691 | Q9: =+SUM(E9:P9) -> 16249 | R9: =Q9/Q10 -> 0.27081667 | S9: 0
D10: Budget | E10: 4000 | F10: 5000 | G10: 5000 | H10: 5500 | I10: 5500 | J10: 4500 | K10: 4500 | L10: 5500 | M10: 5500 | N10: 4500 | O10: 5000 | P10: 5500 | Q10: =SUM(E10:P10) -> 60000 | S10: =Q10/$Q$230 -> 0.0037496485
A11: Ann | B11: C-Anchored | C11: AUSTRALIAN MILITARY BANK | D11: Actual | E11: 2144 | F11: 8159.5 | G11: 4008 | Q11: =+SUM(E11:P11) -> 14311.5 | R11: =Q11/Q12 -> 0.715575 | S11: 0
D12: Budget | E12: 4000 | F12: 4000 | G12: 1500 | H12: 1500 | I12: 1500 | K12: 2000 | L12: 2000 | M12: 2000 | P12: 1500 | Q12: =SUM(E12:P12) -> 20000 | S12: =Q12/$Q$230 -> 0.0012498828
A13: Ann | B13: C-Anchored | C13: CORNERSTONE HEALTH | D13: Actual | E13: 5435.32 | F13: 7118.27 | G13: 10258.05 | Q13: =+SUM(E13:P13) -> 22811.64 | R13: =Q13/Q14 -> 0.380194 | S13: 0
D14: Budget | E14: 6000 | F14: 6000 | G14: 6500 | H14: 4000 | I14: 4000 | J14: 3000 | K14: 4000 | L14: 3000 | M14: 6000 | N14: 6000 | O14: 5500 | P14: 6000 | Q14: =SUM(E14:P14) -> 60000 | S14: =Q14/$Q$230 -> 0.0037496485
A15: Ann | B15: C-Anchored | C15: Dooleys | D15: Actual | E15: 1304.78 | G15: 44262 | Q15: =+SUM(E15:P15) -> 45566.78 | R15: =Q15/Q16 -> 0.650954 | S15: 0
D16: Budget | E16: 2500 | F16: 8000 | G16: 8000 | H16: 5000 | I16: 8000 | J16: 2000 | K16: 2000 | L16: 7000 | M16: 8000 | N16: 5000 | O16: 8000 | P16: 6500 | Q16: =SUM(E16:P16) -> 70000 | S16: =Q16/$Q$230 -> 0.0043745899
A17: Ann | B17: C-Anchored | C17: Edge Early Learning | D17: Actual | E17: 10031.03 | F17: 55953.408 | Q17: =+SUM(E17:P17) -> 65984.438 | R17: =Q17/Q18 -> 1.0997406 | S17: 0
D18: Budget | E18: 20000 | F18: 20000 | G18: 20000 | Q18: =SUM(E18:P18) -> 60000 | S18: =Q18/$Q$230 -> 0.0037496485
A19: Ann | B19: C-Anchored | C19: EG Australia | D19: Actual | E19: 7328.96 | F19: 3975.5527 | G19: 1436.6626 | Q19: =+SUM(E19:P19) -> 12741.175 | R19: =Q19/Q20 -> 0.10617646 | S19: 0
D20: Budget | E20: 10000 | F20: 10000 | G20: 10000 | H20: 10000 | I20: 10000 | J20: 10000 | K20: 10000 | L20: 10000 | M20: 10000 | N20: 10000 | O20: 10000 | P20: 10000 | Q20: =SUM(E20:P20) -> 120000 | S20: =Q20/$Q$230 -> 0.0074992969
A21: Ann | B21: C-Anchored | C21: Hall and Prior | D21: Actual | E21: 12661.63 | F21: 7797.22 | G21: 16019.05 | Q21: =+SUM(E21:P21) -> 36477.9 | R21: =Q21/Q22 -> 0.607965 | S21: 0
D22: Budget | E22: 5000 | F22: 5500 | G22: 5000 | H22: 3500 | I22: 4000 | J22: 3500 | K22: 5500 | L22: 4000 | M22: 7500 | N22: 5500 | O22: 5500 | P22: 5500 | Q22: =SUM(E22:P22) -> 60000 | S22: =Q22/$Q$230 -> 0.0037496485
A23: Ann | B23: C-Anchored | C23: HARDI AGED CARE | D23: Actual | E23: 7674.8 | F23: 10950.26 | G23: 5299.2692 | Q23: =+SUM(E23:P23) -> 23924.329 | R23: =Q23/Q24 -> 0.39873882 | S23: 0
D24: Budget | E24: 5500 | F24: 5500 | G24: 4500 | H24: 5500 | I24: 5500 | J24: 3000 | K24: 3500 | L24: 5500 | M24: 5500 | N24: 5500 | O24: 5000 | P24: 5500 | Q24: =SUM(E24:P24) -> 60000 | S24: =Q24/$Q$230 -> 0.0037496485
A25: Ann | B25: C-Anchored | C25: RSL LIFECARE | D25: Actual | E25: 314 | G25: 330 | Q25: =+SUM(E25:P25) -> 644 | R25: =Q25/Q26 -> 0.01288 | S25: 0
D26: Budget | E26: 6000 | F26: 6000 | G26: 6000 | H26: 3000 | I26: 3000 | J26: 3000 | K26: 4000 | L26: 3000 | M26: 3000 | N26: 3000 | O26: 5000 | P26: 5000 | Q26: =SUM(E26:P26) -> 50000 | S26: =Q26/$Q$230 -> 0.0031247071
A27: Ann | B27: C-Anchored | C27: MYCAR | D27: Actual | E27: 6185.5 | F27: 6568.12 | G27: 1233 | Q27: =+SUM(E27:P27) -> 13986.62 | R27: =Q27/Q28 -> 0.19980886 | S27: 0
D28: Budget | E28: 4000 | F28: 4000 | G28: 4500 | H28: 5500 | I28: 15000 | J28: 4500 | K28: 2500 | L28: 4000 | M28: 15000 | N28: 5500 | O28: 2500 | P28: 3000 | Q28: =SUM(E28:P28) -> 70000 | S28: =Q28/$Q$230 -> 0.0043745899
A29: Ann | B29: C-Anchored | C29: MYCAR - ALSCO | D29: Actual | F29: 242.5 | Q29: =+SUM(E29:P29) -> 242.5 | R29: =Q29/Q30 -> 0.00080833333 | S29: 0
D30: Budget | M30: 300000 | Q30: =SUM(E30:P30) -> 300000 | S30: =Q30/$Q$230 -> 0.018748242
A31: Ann | B31: C-Anchored | C31: SYDNEY CRICKET & SPORTS GRD TR | D31: Actual | E31: 6727 | G31: 1376 | Q31: =+SUM(E31:P31) -> 8103 | R31: =Q31/Q32 -> 0.073663636 | S31: 0
D32: Budget | E32: 25000 | F32: 25000 | G32: 20000 | H32: 10000 | K32: 20000 | P32: 10000 | Q32: =SUM(E32:P32) -> 110000 | S32: =Q32/$Q$230 -> 0.0068743555
A33: Ann | B33: C-Anchored | C33: Whiddon | D33: Actual | E33: 13608 | F33: 8708.08 | G33: 40710.54 | Q33: =+SUM(E33:P33) -> 63026.62 | R33: =Q33/Q34 -> 0.21008873 | S33: 0
D34: Budget | E34: 17000 | F34: 17000 | G34: 113000 | H34: 17000 | I34: 17000 | J34: 17000 | K34: 17000 | L34: 17000 | M34: 17000 | N34: 17000 | O34: 17000 | P34: 17000 | Q34: =SUM(E34:P34) -> 300000 | S34: =Q34/$Q$230 -> 0.018748242
A35: Ann | B35: C-Anchored | C35: WOOLWORTHS - METRO | D35: Actual | E35: 8256.54 | F35: 9453.9 | G35: 7183 | Q35: =+SUM(E35:P35) -> 24893.44 | R35: =Q35/Q36 -> 0.2489344 | S35: 0
D36: Budget | E36: 8500 | F36: 8500 | G36: 8500 | H36: 8500 | I36: 8500 | J36: 8500 | K36: 8000 | L36: 8000 | M36: 8500 | N36: 8500 | O36: 8000 | P36: 8000 | Q36: =SUM(E36:P36) -> 100000 | S36: =Q36/$Q$230 -> 0.0062494141
A37: Ann | B37: C-Anchored | C37: WOOLWORTHS - ALSCO | D37: Actual | E37: 206250 | F37: 165000 | Q37: =+SUM(E37:P37) -> 371250 | R37: =Q37/Q38 -> 0.80706522 | S37: 0
D38: Budget | E38: 210000 | G38: 165000 | N38: 85000 | Q38: =SUM(E38:P38) -> 460000 | S38: =Q38/$Q$230 -> 0.028747305
A39: Ann | B39: C-Anchored | C39: Fantastic Furniture | D39: Actual | E39: 5868 | F39: 26762 | G39: 12594 | Q39: =+SUM(E39:P39) -> 45224 | R39: =Q39/Q40 -> 0.32302857 | S39: 0
D40: Budget | E40: 10000 | F40: 10000 | G40: 6000 | H40: 10000 | I40: 20000 | J40: 40000 | K40: 5000 | L40: 6000 | M40: 8000 | N40: 8000 | O40: 7000 | P40: 10000 | Q40: =SUM(E40:P40) -> 140000 | S40: =Q40/$Q$230 -> 0.0087491798
...

Sheet Working
A1: Customer Group | B1: Amount
A2: AFTERCARE/STRIDE | B2: 5011.4492
A3: Anytime Fitness | B3: 15778.285
A4: Apiam Animal Health | B4: 11468.5
A5: ARCARE | B5: 30581
A6: Aus Nursing Home (NHF) | B6: 9691
A7: AUSTRALIAN MILITARY BANK | B7: 4008
A8: Aveo Retirement Villages | B8: 5225.3636
A9: BAPCOR | B9: 3234
A10: BENETAS | B10: 514
A11: BIG RIVER GROUP | B11: 5203.6
A12: Canterbury League Club | B12: 330
A13: Cater Care | B13: 18574
... A86: ZZ-Teamwear & Fitness-OTHER | B86: 1281
