Workbook

Sheet Snapshot
A2: TIG Weekly Financial Snapshot as of the 4th of August 2025
A4: Description | C4: 45839 | D4: 45870 | E4: 45901 | F4: 45931 | G4: 45962 | H4: 45992 | I4: 46023 | J4: 46054 | K4: 46082 | L4: 46113 | M4: 46143 | N4: 46174 | O4: Total
A5: Monthly Shipped Sales
A6: HQ | C6: 1350599.8 | D6: 27558 | O6: =SUM(C6:N6) -> 1378157.8
C7: =C6/C13 -> 0.79884071 | D7: =D6/#REF! -> #REF! | E7: =E6/#REF! -> #REF! | F7: =F6/#REF! -> #REF! | G7: =G6/#REF! -> #REF! | H7: =H6/#REF! -> #REF! | I7: =I6/#REF! -> #REF! | J7: =J6/#REF! -> #REF! | K7: =K6/#REF! -> #REF! | ... N7: =N6/#REF! -> #REF! | O7: =SUM(C7:N7) -> #REF!
A8: 3PL | C8: 340099.96 | D8: 0 | O8: =SUM(C8:N8) -> 340099.96
C9: =C8/C13 -> 0.20115929 | O9: =SUM(C9:N9) -> 0.20115929
A10: NZ | C10: 0 | O10: =SUM(C10:N10) -> 0
C11: =C10/C12 -> #VALUE! | D11: =#REF!/D10 -> #REF! | E11: =#REF!/E10 -> #REF! | F11: =#REF!/F10 -> #REF! | G11: =#REF!/G10 -> #REF! | H11: =#REF!/H10 -> #REF! | I11: =#REF!/I10 -> #REF! | J11: =#REF!/J10 -> #REF! | K11: =#REF!/K10 -> #REF! | ... O11: =#REF!/O10 -> #REF!
A12: Shipped Sales Total | C12: Shipped | D12: =SUM(D6+D8+D10) -> 27558 | O12: =SUM(C12:N12) -> 27558
A13: Invoiced Sales Total | C13: 1690699.7 | D13: ='25-26 Budget-Actual Invoiced'!F318 -> 0 | E13: ='25-26 Budget-Actual Invoiced'!G318 -> 0 | F13: ='25-26 Budget-Actual Invoiced'!H318 -> 0 | G13: ='25-26 Budget-Actual Invoiced'!I318 -> 0 | H13: ='25-26 Budget-Actual Invoiced'!J318 -> 0 | I13: ='25-26 Budget-Actual Invoiced'!K318 -> 0 | J13: ='25-26 Budget-Actual Invoiced'!L318 -> 0 | K13: ='25-26 Budget-Actual Invoiced'!M318 -> 0 | ... N13: ='25-26 Budget-Actual Invoiced'!P318 -> 0 | O13: =SUM(C13:N13) -> 1690699.7
A14: Budget | C14: 1435665 | D14: 1507367 | E14: 1732767 | F14: 1157167 | G14: 1168617 | H14: 1082167 | I14: 1077167 | J14: 1196667 | K14: 1630917 | L14: 1429367 | M14: 1255817 | N14: 1327815 | O14: =SUM(C14:N14) -> 16001500
A15: % of Budget | C15: =C13/C14 -> 1.1776422 | D15: =D12/D14 -> 0.01828221 | E15: =E12/E14 -> 0 | F15: =F12/F14 -> 0 | G15: =G12/G14 -> 0 | H15: =H12/H14 -> 0 | I15: =I12/I14 -> 0 | J15: =J12/J14 -> 0 | K15: =K12/K14 -> 0 | ... O15: =O12/O14 -> 0.0017222135
A16: $ Variance | C16: =C13-C14 -> 255034.71 | D16: =D12-D14 -> -1479809 | E16: =E12-E14 -> -1732767 | F16: =F12-F14 -> -1157167 | G16: =G12-G14 -> -1168617 | H16: =H12-H14 -> -1082167 | I16: =I12-I14 -> -1077167 | J16: =J12-J14 -> -1196667 | K16: =K12-K14 -> -1630917 | ... N16: =N12-N14 -> -1327815 | O16: =SUM(C16:N16) -> -14283242
A17: % Variance | C17: =C16/C14 -> 0.17764221 | D17: =D16/D14 -> -0.98171779 | E17: =E16/E14 -> -1 | F17: =F16/F14 -> -1 | G17: =G16/G14 -> -1 | H17: =H16/H14 -> -1 | I17: =I16/I14 -> -1 | J17: =J16/J14 -> -1 | ... O17: =O16/O14 -> -0.89261896
A19: HQ WIP | B19: Order $ | C19: 0 | D19: 491671 | E19: 165000 | F19: 0 | G19: 0 | H19: 0 | I19: 0 | J19: 0 | K19: 0 | L19: 0 | M19: 0 | N19: 0 | O19: =SUM(C19:N19) -> 656671
B20: Order QTY | C20: 0 | D20: 859 | E20: 1 | F20: 0 | G20: 0 | H20: 0 | I20: 0 | J20: 0 | K20: 0 | L20: 0 | M20: 0 | N20: 0 | O20: =SUM(C20:N20) -> 860
B21: B/O $ | C21: 0 | D21: 51863 | E21: 0 | F21: 0 | G21: 0 | H21: 0 | I21: 0 | J21: 0 | K21: 0 | L21: 0 | M21: 0 | N21: 0 | O21: =SUM(C21:N21) -> 51863
B22: B/O QTY | C22: 0 | D22: 208 | E22: 0 | F22: 0 | G22: 0 | H22: 0 | I22: 0 | J22: 0 | K22: 0 | L22: 0 | M22: 0 | N22: 0 | O22: =SUM(C22:N22) -> 208
B23: BOOKED $ | C23: 0 | D23: 285754 | E23: 0 | F23: 0 | G23: 0 | H23: 0 | I23: 0 | J23: 0 | K23: 0 | L23: 0 | M23: 0 | N23: 0 | O23: =SUM(C23:N23) -> 285754
B24: BOOKED QTY | C24: 0 | D24: 315 | E24: 0 | F24: 0 | G24: 0 | H24: 0 | I24: 0 | J24: 0 | K24: 0 | L24: 0 | M24: 0 | N24: 0 | O24: =SUM(C24:N24) -> 315
A25: 3PL WIP | B25: Order $ | C25: 0 | D25: 114235 | E25: 0 | F25: 0 | G25: 0 | H25: 0 | I25: 0 | J25: 0 | K25: 0 | L25: 0 | M25: 0 | N25: 0 | O25: =SUM(C25:N25) -> 114235
B26: Order QTY | C26: 0 | D26: 598 | E26: 0 | F26: 0 | G26: 0 | H26: 0 | I26: 0 | J26: 0 | K26: 0 | L26: 0 | M26: 0 | N26: 0 | O26: =SUM(C26:N26) -> 598
B27: B/O $ | C27: 0 | D27: 67986 | E27: 0 | F27: 0 | G27: 0 | H27: 0 | J27: 0 | K27: 0 | L27: 0 | M27: 0 | N27: 0 | O27: =SUM(C27:N27) -> 67986
B28: B/O QTY | C28: 0 | D28: 332 | E28: 0 | F28: 0 | G28: 0 | H28: 0 | J28: 0 | K28: 0 | L28: 0 | M28: 0 | N28: 0 | O28: =SUM(C28:N28) -> 332
A29: NZ WIP | B29: Order $ | C29: 0 | D29: 0 | E29: 169052 | F29: 0 | G29: 0 | H29: 0 | I29: 0 | J29: 0 | K29: 0 | L29: 0 | M29: 0 | N29: 0 | O29: =SUM(C29:N29) -> 169052
B30: Order QTY | C30: 0 | D30: 0 | E30: 143 | F30: 0 | G30: 0 | H30: 0 | I30: 0 | J30: 0 | K30: 0 | L30: 0 | M30: 0 | N30: 0 | O30: =SUM(C30:N30) -> 143
B31: B/O $ | C31: 0 | D31: 0 | E31: 0 | F31: 0 | G31: 0 | H31: 0 | J31: 0 | K31: 0 | L31: 0 | M31: 0 | N31: 0 | O31: =SUM(C31:N31) -> 0
B32: B/O QTY | C32: 0 | D32: 0 | E32: 0 | F32: 0 | G32: 0 | H32: 0 | J32: 0 | K32: 0 | L32: 0 | M32: 0 | N32: 0 | O32: =SUM(C32:N32) -> 0
A33: Total WIP | B33: Value | C33: =SUM(C27,C25,C23,C21,C19,C29,C31) -> 0 | D33: =SUM(D27,D25,D23,D21,D19,D29,D31) -> 1011509 | E33: =SUM(E27,E25,E23,E21,E19,E29,E31) -> 334052 | F33: =SUM(F27,F25,F23,F21,F19,F29,F31) -> 0 | G33: =SUM(G27,G25,G23,G21,G19,G29,G31) -> 0 | H33: =SUM(H27,H25,H23,H21,H19,H29,H31) -> 0 | I33: =SUM(I27,I25,I23,I21,I19,I29,I31) -> 0 | J33: =SUM(J27,J25,J23,J21,J19,J29,J31) -> 0 | ... N33: =SUM(N27,N25,N23,N21,N19,N29,N31) -> 0 | O33: =SUM(C33:N33) -> 1345561
B34: Orders | C34: =SUM(C28,C26,C24,C22,C20,C30,C32) -> 0 | D34: =SUM(D28,D26,D24,D22,D20,D30,D32) -> 2312 | E34: =SUM(E28,E26,E24,E22,E20,E30,E32) -> 144 | F34: =SUM(F28,F26,F24,F22,F20,F30,F32) -> 0 | G34: =SUM(G28,G26,G24,G22,G20,G30,G32) -> 0 | H34: =SUM(H28,H26,H24,H22,H20,H30,H32) -> 0 | I34: =SUM(I28,I26,I24,I22,I20,I30,I32) -> 0 | J34: =SUM(J28,J26,J24,J22,J20,J30,J32) -> 0 | ... N34: =SUM(N28,N26,N24,N22,N20,N30,N32) -> 0 | O34: =SUM(C34:N34) -> 2456

Sheet 25-26 Budget-Actual Invoiced
A1: Sales Budget Vs Actual Invoiced- 1st July 2025 to 30 June 2026 | Q1: Annual | S1: % Of Sales
A2: Account Manager | B2: Non-Report | C2: Customer Name | E2: 45839 | F2: 45870 | G2: 45901 | H2: 45931 | I2: 45962 | J2: 45992 | K2: 46023 | L2: 46054 | M2: 46082 | N2: 46113 | O2: 46143 | P2: 46174 | Q2: Total | R2: % to Budget
A3: Ann | B3: C-Anchored | C3: WINNING APPLIANCES | D3: Actual | E3: 770 | Q3: =+SUM(E3:P3) -> 770 | R3: =Q3/Q4 -> 0.014 | S3: 0
D4: Budget | E4: 3000 | F4: 4200 | G4: 1600 | H4: 7500 | I4: 5450 | J4: 1500 | K4: 4000 | L4: 4000 | M4: 7750 | N4: 6700 | O4: 4650 | P4: 4650 | Q4: =SUM(E4:P4) -> 55000 | S4: =Q4/$Q$319 -> 0.0034371778
D5: GPM%
A6: Ann | B6: C-Anchored | C6: HARVEY NORMAN | D6: Actual | E6: 179440.36 | Q6: =+SUM(E6:P6) -> 179440.36 | R6: =Q6/Q7 -> 0.16238947 | S6: 0
D7: Budget | E7: 105000 | F7: 100000 | G7: 75000 | H7: 75000 | I7: 100000 | J7: 100000 | K7: 80000 | L7: 80000 | M7: 95000 | N7: 95000 | O7: 100000 | P7: 100000 | Q7: =SUM(E7:P7) -> 1105000 | S7: =Q7/$Q$319 -> 0.069056026
D8: GPM%
A9: Ann | B9: C-Anchored | C9: HARVEY NORMAN NZ | D9: Actual | Q9: =+SUM(E9:P9) -> 0 | R9: =Q9/Q10 -> 0 | S9: 0
D10: Budget | G10: 220000 | H10: 20000 | I10: 20000 | J10: 15000 | K10: 15000 | L10: 15000 | M10: 15000 | N10: 15000 | O10: 15000 | P10: 15000 | Q10: =SUM(E10:P10) -> 365000 | S10: =Q10/$Q$319 -> 0.022810362
D11: GPM%
A12: Ann | B12: C-Anchored | C12: Aus Nursing Home (NHF) | D12: Actual | E12: 2856 | Q12: =+SUM(E12:P12) -> 2856 | R12: =Q12/Q13 -> 0.0476 | S12: 0
D13: Budget | E13: 4000 | F13: 5000 | G13: 5000 | H13: 5500 | I13: 5500 | J13: 4500 | K13: 4500 | L13: 5500 | M13: 5500 | N13: 4500 | O13: 5000 | P13: 5500 | Q13: =SUM(E13:P13) -> 60000 | S13: =Q13/$Q$319 -> 0.0037496485
D14: GPM%
A15: Ann | B15: C-Anchored | C15: AUSTRALIAN MILITARY BANK | D15: Actual | E15: 2144 | Q15: =+SUM(E15:P15) -> 2144 | R15: =Q15/Q16 -> 0.1072 | S15: 0
D16: Budget | E16: 4000 | F16: 4000 | G16: 1500 | H16: 1500 | I16: 1500 | K16: 2000 | L16: 2000 | M16: 2000 | P16: 1500 | Q16: =SUM(E16:P16) -> 20000 | S16: =Q16/$Q$319 -> 0.0012498828
D17: GPM%
A18: Ann | B18: C-Anchored | C18: CORNERSTONE HEALTH | D18: Actual | E18: 5435.32 | Q18: =+SUM(E18:P18) -> 5435.32 | R18: =Q18/Q19 -> 0.090588667 | S18: 0
D19: Budget | E19: 6000 | F19: 6000 | G19: 6500 | H19: 4000 | I19: 4000 | J19: 3000 | K19: 4000 | L19: 3000 | M19: 6000 | N19: 6000 | O19: 5500 | P19: 6000 | Q19: =SUM(E19:P19) -> 60000 | S19: =Q19/$Q$319 -> 0.0037496485
D20: GPM%
A21: Ann | B21: C-Anchored | C21: DOOLEYS LIDCOMBE CATHOLIC CLUB | D21: Actual | E21: 1304.78 | Q21: =+SUM(E21:P21) -> 1304.78 | R21: =Q21/Q22 -> 0.018639714 | S21: 0
D22: Budget | E22: 2500 | F22: 8000 | G22: 8000 | H22: 5000 | I22: 8000 | J22: 2000 | K22: 2000 | L22: 7000 | M22: 8000 | N22: 5000 | O22: 8000 | P22: 6500 | Q22: =SUM(E22:P22) -> 70000 | S22: =Q22/$Q$319 -> 0.0043745899
D23: GPM%
A24: Ann | B24: C-Anchored | C24: Edge Early Learning | D24: Actual | E24: 10031.03 | Q24: =+SUM(E24:P24) -> 10031.03 | R24: =Q24/Q25 -> 0.16718383 | S24: 0
D25: Budget | E25: 20000 | F25: 20000 | G25: 20000 | Q25: =SUM(E25:P25) -> 60000 | S25: =Q25/$Q$319 -> 0.0037496485
D26: GPM%
A27: Ann | B27: C-Anchored | C27: EG Group | D27: Actual | E27: 7328.96 | Q27: =+SUM(E27:P27) -> 7328.96 | R27: =Q27/Q28 -> 0.061074667 | S27: 0
D28: Budget | E28: 10000 | F28: 10000 | G28: 10000 | H28: 10000 | I28: 10000 | J28: 10000 | K28: 10000 | L28: 10000 | M28: 10000 | N28: 10000 | O28: 10000 | P28: 10000 | Q28: =SUM(E28:P28) -> 120000 | S28: =Q28/$Q$319 -> 0.0074992969
D29: GPM%
A30: Ann | B30: C-Anchored | C30: Hall & Prior | D30: Actual | E30: 12661.63 | Q30: =+SUM(E30:P30) -> 12661.63 | R30: =Q30/Q31 -> 0.21102717 | S30: 0
D31: Budget | E31: 5000 | F31: 5500 | G31: 5000 | H31: 3500 | I31: 4000 | J31: 3500 | K31: 5500 | L31: 4000 | M31: 7500 | N31: 5500 | O31: 5500 | P31: 5500 | Q31: =SUM(E31:P31) -> 60000 | S31: =Q31/$Q$319 -> 0.0037496485
D32: GPM%
A33: Ann | B33: C-Anchored | C33: HARDI AGED CARE (HAC) | D33: Actual | E33: 7674.8 | Q33: =+SUM(E33:P33) -> 7674.8 | R33: =Q33/Q34 -> 0.12791333 | S33: 0
D34: Budget | E34: 5500 | F34: 5500 | G34: 4500 | H34: 5500 | I34: 5500 | J34: 3000 | K34: 3500 | L34: 5500 | M34: 5500 | N34: 5500 | O34: 5000 | P34: 5500 | Q34: =SUM(E34:P34) -> 60000 | S34: =Q34/$Q$319 -> 0.0037496485
D35: GPM%
A36: Ann | B36: C-Anchored | C36: RSL LIFECARE | D36: Actual | E36: 314 | Q36: =+SUM(E36:P36) -> 314 | R36: =Q36/Q37 -> 0.00628 | S36: 0
D37: Budget | E37: 6000 | F37: 6000 | G37: 6000 | H37: 3000 | I37: 3000 | J37: 3000 | K37: 4000 | L37: 3000 | M37: 3000 | N37: 3000 | O37: 5000 | P37: 5000 | Q37: =SUM(E37:P37) -> 50000 | S37: =Q37/$Q$319 -> 0.0031247071
D38: GPM%
A39: Ann | B39: C-Anchored | C39: MYCAR | D39: Actual | E39: 6185.5 | Q39: =+SUM(E39:P39) -> 6185.5 | R39: =Q39/Q40 -> 0.088364286 | S39: 0
D40: Budget | E40: 4000 | F40: 4000 | G40: 4500 | H40: 5500 | I40: 15000 | J40: 4500 | K40: 2500 | L40: 4000 | M40: 15000 | N40: 5500 | O40: 2500 | P40: 3000 | Q40: =SUM(E40:P40) -> 70000 | S40: =Q40/$Q$319 -> 0.0043745899
...
