Workbook

Sheet Snapshot
A2: TIG Weekly Financial Snapshot as of the 5th of February 2026
A4: Description | C4: 45839 | D4: 45870 | E4: 45901 | F4: 45931 | G4: 45962 | H4: 45992 | I4: 46023 | J4: 46054 | K4: 46082 | L4: 46113 | M4: 46143 | N4: 46174 | O4: Total
A5: Monthly Shipped Sales
A6: HQ | C6: 1350599.8 | D6: 1039303.9 | E6: 1184140.2 | F6: 948443 | G6: 782541.5 | H6: 485498 | I6: 850395.55 | J6: 60494 | O6: =SUM(C6:N6) -> 6701415.9
C7: =C6/C13 -> 0.79884071 | D7: 0.833985 | E7: 0.83818736 | F7: =F6/F13 -> 0.79780964 | G7: =G6/G13 -> 0.77777171 | H7: =H6/H13 -> 0.41028968 | I7: =I6/I13 -> 0.90881454 | J7: =J6/J12 -> 0.87258932 | K7: =K6/#REF! -> #REF! | L7: =L6/#REF! -> #REF! | M7: =M6/#REF! -> #REF! | N7: =N6/#REF! -> #REF! | O7: =SUM(C7:N7) -> #REF!
A8: 3PL | C8: 340099.96 | D8: 198913.26 | E8: 76883 | F8: 230117.27 | G8: 184951.05 | H8: 685179 | I8: 87155.87 | J8: 8833 | O8: =SUM(C8:N8) -> 1812132.4
C9: =C8/C13 -> 0.20115929 | D9: 0.1596171 | E9: 0.053744379 | F9: =F8/F13 -> 0.19356965 | G9: =G8/G13 -> 0.18382373 | H9: =H8/H13 -> 0.57903817 | I9: =I8/I13 -> 0.093143152 | J9: =J8/J12 -> 0.12741068
A10: NZ | C10: 0 | D10: 7973 | E10: 154595 | F10: 10248 | G10: 38640.41 | H10: 12876 | I10: 8412.83 | J10: 0 | O10: =SUM(C10:N10) -> 232745.24
C11: =C10/C14 -> 0 | D11: 0.0052893555 | E11: 0.10806826 | F11: =F10/F13 -> 0.0086203949 | G11: =G10/G13 -> 0.038404887 | H11: =H10/H13 -> 0.010881384 | I11: =I10/I13 -> 0.0089907599 | J11: =J10/J13 -> 0 | K11: =#REF!/K10 -> #REF! | L11: =#REF!/L10 -> #REF! | M11: =#REF!/M10 -> #REF! | N11: =#REF!/N10 -> #REF! | O11: =#REF!/O10 -> #REF!
A12: Shipped Sales Total | C12: Shipped | D12: Shipped | E12: Shipped | F12: Shipped | G12: Shipped | H12: Shipped | I12: Shipped | J12: =J10+J8+J6 -> 69327
A13: Invoiced Sales Total | C13: 1690699.7 | D13: 1246190.1 | E13: 1415618.2 | F13: 1188808.6 | G13: 1006132.6 | H13: 1183305.4 | I13: 935719.57 | J13: 44504 | K13: ='25-26 Budget-Actual Invoiced'!M272 -> 0 | L13: ='25-26 Budget-Actual Invoiced'!N272 -> 0 | M13: ='25-26 Budget-Actual Invoiced'!O272 -> 0 | N13: ='25-26 Budget-Actual Invoiced'!P272 -> 0 | O13: =SUM(C13:N13) -> 8710978.3
A14: Budget | C14: ='25-26 Budget-Actual Invoiced'!E273 -> 1367915 | D14: ='25-26 Budget-Actual Invoiced'!F273 -> 1447617 | E14: ='25-26 Budget-Actual Invoiced'!G273 -> 1634117 | F14: ='25-26 Budget-Actual Invoiced'!H273 -> 1176017 | G14: ='25-26 Budget-Actual Invoiced'!I273 -> 1174967 | H14: ='25-26 Budget-Actual Invoiced'!J273 -> 1061017 | I14: ='25-26 Budget-Actual Invoiced'!K273 -> 1088017 | J14: ='25-26 Budget-Actual Invoiced'!L273 -> 1260017 | ... N14: ='25-26 Budget-Actual Invoiced'!P273 -> 1358665 | O14: =SUM(C14:N14) -> 16001500
A15: % of Budget | C15: =C13/C14 -> 1.2359684 | D15: =D13/D14 -> 0.86085624 | E15: =E13/E14 -> 0.8662894 | F15: =F13/F14 -> 1.0108771 | G15: =G13/G14 -> 0.85630714 | H15: =H13/H14 -> 1.1152558 | I15: =I13/I14 -> 0.86002293 | J15: =J12/J14 -> 0.055020686 | K15: =K12/K14 -> 0 | L15: =L12/L14 -> 0 | M15: =M12/M14 -> 0 | N15: =N12/N14 -> 0 | O15: =O12/O14 -> 0
A16: $ Variance | C16: =C13-C14 -> 322784.71 | D16: =D13-D14 -> -201426.87 | E16: =E13-E14 -> -218498.76 | F16: =F13-F14 -> 12791.643 | G16: =G13-G14 -> -168834.37 | H16: =H13-H14 -> 122288.41 | I16: =I13-I14 -> -152297.43 | J16: =J12-J14 -> -1190690 | K16: =K12-K14 -> -1386767 | L16: =L12-L14 -> -1446717 | M16: =M12-M14 -> -1599667 | N16: =N12-N14 -> -1358665 | O16: =SUM(C16:N16) -> -7265698.7
A17: % Variance | C17: =C16/C14 -> 0.2359684 | D17: =D16/D14 -> -0.13914376 | E17: =E16/E14 -> -0.1337106 | F17: =F16/F14 -> 0.01087709 | G17: =G16/G14 -> -0.14369286 | H17: =H16/H14 -> 0.11525584 | I17: =I16/I14 -> -0.13997707 | J17: =J16/J14 -> -0.94497931 | ... O17: =O16/O14 -> -0.4540636
A19: HQ WIP | B19: Order $ | C19: 0 | D19: 0 | E19: 0 | F19: 0 | G19: 0 | H19: 0 | I19: 0 | J19: 425355 | K19: 86437 | L19: 331995 | M19: 0 | N19: 0 | O19: =SUM(C19:N19) -> 843787
B20: Order QTY | C20: 0 | D20: 0 | E20: 0 | F20: 0 | G20: 0 | H20: 0 | I20: 0 | J20: 809 | K20: 2 | L20: 1 | M20: 0 | N20: 0 | O20: =SUM(C20:N20) -> 812
B21: B/O $ | C21: 0 | D21: 0 | E21: 0 | F21: 0 | G21: 0 | H21: 0 | I21: 0 | J21: 10480 | K21: 80 | L21: 0 | M21: 0 | N21: 0 | O21: =SUM(C21:N21) -> 10560
B22: B/O QTY | C22: 0 | D22: 0 | E22: 0 | F22: 0 | G22: 0 | H22: 0 | I22: 0 | J22: 104 | K22: 1 | L22: 0 | M22: 0 | N22: 0 | O22: =SUM(C22:N22) -> 105
B23: BOOKED $ | C23: 0 | D23: 0 | E23: 0 | F23: 0 | G23: 0 | H23: 0 | I23: 0 | J23: 144427 | K23: 0 | L23: 0 | M23: 0 | N23: 0 | O23: =SUM(C23:N23) -> 144427
B24: BOOKED QTY | C24: 0 | D24: 0 | E24: 0 | F24: 0 | G24: 0 | H24: 0 | I24: 0 | J24: 69 | K24: 0 | L24: 0 | M24: 0 | N24: 0 | O24: =SUM(C24:N24) -> 69
A25: 3PL WIP | B25: Order $ | C25: 0 | D25: 0 | E25: 0 | F25: 0 | G25: 0 | H25: 0 | I25: 0 | J25: 20795 | K25: 0 | L25: 0 | M25: 0 | N25: 0 | O25: =SUM(C25:N25) -> 20795
B26: Order QTY | C26: 0 | D26: 0 | E26: 0 | F26: 0 | G26: 0 | H26: 0 | I26: 0 | J26: 235 | K26: 0 | L26: 0 | M26: 0 | N26: 0 | O26: =SUM(C26:N26) -> 235
B27: B/O $ | C27: 0 | D27: 0 | E27: 0 | F27: 0 | G27: 0 | H27: 0 | I27: 0 | J27: 0 | K27: 0 | L27: 0 | M27: 0 | N27: 0 | O27: =SUM(C27:N27) -> 0
B28: B/O QTY | C28: 0 | D28: 0 | E28: 0 | F28: 0 | G28: 0 | H28: 0 | I28: 0 | J28: 0 | K28: 0 | L28: 0 | M28: 0 | N28: 0 | O28: =SUM(C28:N28) -> 0
A29: NZ WIP | B29: Order $ | C29: 0 | D29: 0 | E29: 0 | F29: 0 | G29: 0 | H29: 0 | I29: 0 | J29: 8125 | K29: 0 | L29: 0 | M29: 0 | N29: 0 | O29: =SUM(C29:N29) -> 8125
B30: Order QTY | C30: 0 | D30: 0 | E30: 0 | F30: 0 | G30: 0 | H30: 0 | I30: 0 | J30: 22 | K30: 0 | L30: 0 | M30: 0 | N30: 0 | O30: =SUM(C30:N30) -> 22
B31: B/O $ | C31: 0 | D31: 0 | E31: 0 | F31: 0 | G31: 0 | H31: 0 | I31: 0 | J31: 0 | K31: 0 | L31: 0 | M31: 0 | N31: 0 | O31: =SUM(C31:N31) -> 0
B32: B/O QTY | C32: 0 | D32: 0 | E32: 0 | F32: 0 | G32: 0 | H32: 0 | I32: 0 | J32: 0 | K32: 0 | L32: 0 | M32: 0 | N32: 0 | O32: =SUM(C32:N32) -> 0
A33: Total WIP | B33: Value | C33: =SUM(C27,C25,C23,C21,C19,C29,C31) -> 0 | D33: =SUM(D27,D25,D23,D21,D19,D29,D31) -> 0 | E33: =SUM(E27,E25,E23,E21,E19,E29,E31) -> 0 | F33: =SUM(F27,F25,F23,F21,F19,F29,F31) -> 0 | G33: =SUM(G27,G25,G23,G21,G19,G29,G31) -> 0 | H33: =SUM(H27,H25,H23,H21,H19,H29,H31) -> 0 | I33: =SUM(I27,I25,I23,I21,I19,I29,I31) -> 0 | J33: =SUM(J27,J25,J23,J21,J19,J29,J31) -> 609182 | ... N33: =SUM(N27,N25,N23,N21,N19,N29,N31) -> 0 | O33: =SUM(C33:N33) -> 1027694
B34: Orders | C34: =SUM(C28,C26,C24,C22,C20,C30,C32) -> 0 | D34: =SUM(D28,D26,D24,D22,D20,D30,D32) -> 0 | E34: =SUM(E28,E26,E24,E22,E20,E30,E32) -> 0 | F34: =SUM(F28,F26,F24,F22,F20,F30,F32) -> 0 | G34: =SUM(G28,G26,G24,G22,G20,G30,G32) -> 0 | H34: =SUM(H28,H26,H24,H22,H20,H30,H32) -> 0 | I34: =SUM(I28,I26,I24,I22,I20,I30,I32) -> 0 | J34: =SUM(J28,J26,J24,J22,J20,J30,J32) -> 1239 | ... N34: =SUM(N28,N26,N24,N22,N20,N30,N32) -> 0 | O34: =SUM(C34:N34) -> 1243

Sheet 25-26 Budget-Actual Invoiced
A1: Sales Budget Vs Actual Invoiced- 1st July 2025 to 30 June 2026 | Q1: Annual | S1: % Of Sales
A2: Account Manager | B2: Non-Report | C2: Customer Name | E2: 45839 | F2: 45870 | G2: 45901 | H2: 45931 | I2: 45962 | J2: 45992 | K2: 46023 | L2: 46054 | M2: 46082 | N2: 46113 | O2: 46143 | P2: 46174 | Q2: Total | R2: % to Budget
A3: Ann | B3: C-Anchored | C3: HARVEY NORMAN | D3: Actual | E3: 179440.36 | F3: 138218.8 | G3: 37125.06 | H3: 166752.29 | I3: 93818.64 | J3: 61451.38 | K3: 71695.5 | Q3: =+SUM(E3:P3) -> 748502.03 | R3: =Q3/Q4 -> 0.6773774 | S3: 0
D4: Budget | E4: 105000 | F4: 100000 | G4: 75000 | H4: 75000 | I4: 100000 | J4: 100000 | K4: 80000 | L4: 80000 | M4: 95000 | N4: 95000 | O4: 100000 | P4: 100000 | Q4: =SUM(E4:P4) -> 1105000 | S4: =Q4/$Q$273 -> 0.069056026
A5: Ann | B5: C-Anchored | C5: HARVEY NORMAN NZ | D5: Actual | F5: 7973.4671 | G5: 154525.83 | H5: 10166.72 | I5: 35685.83 | J5: 12876.71 | K5: 6485.4 | Q5: =+SUM(E5:P5) -> 227713.95 | R5: =Q5/Q6 -> 0.62387384 | S5: 0
D6: Budget | G6: 220000 | H6: 20000 | I6: 20000 | J6: 15000 | K6: 15000 | L6: 15000 | M6: 15000 | N6: 15000 | O6: 15000 | P6: 15000 | Q6: =SUM(E6:P6) -> 365000 | S6: =Q6/$Q$273 -> 0.022810362
A7: Ann | B7: C-Anchored | C7: Aus Nursing Home (NHF) | D7: Actual | E7: 2856 | F7: 3702 | G7: 9691 | H7: 5660 | I7: 2115 | J7: 788.5 | K7: 2497 | Q7: =+SUM(E7:P7) -> 27309.5 | R7: =Q7/Q8 -> 0.45515833 | S7: 0
D8: Budget | E8: 4000 | F8: 5000 | G8: 5000 | H8: 5500 | I8: 5500 | J8: 4500 | K8: 4500 | L8: 5500 | M8: 5500 | N8: 4500 | O8: 5000 | P8: 5500 | Q8: =SUM(E8:P8) -> 60000 | S8: =Q8/$Q$273 -> 0.0037496485
A9: Ann | B9: C-Anchored | C9: CORNERSTONE HEALTH | D9: Actual | E9: 5435.32 | F9: 7118.27 | G9: 10258.05 | H9: 10005.67 | I9: 9010.55 | J9: 6255.5 | K9: 4952.32 | Q9: =+SUM(E9:P9) -> 53035.68 | R9: =Q9/Q10 -> 0.883928 | S9: 0
D10: Budget | E10: 6000 | F10: 6000 | G10: 6500 | H10: 4000 | I10: 4000 | J10: 3000 | K10: 4000 | L10: 3000 | M10: 6000 | N10: 6000 | O10: 5500 | P10: 6000 | Q10: =SUM(E10:P10) -> 60000 | S10: =Q10/$Q$273 -> 0.0037496485
A11: Ann | B11: C-Anchored | C11: Dooleys | D11: Actual | E11: 1304.78 | G11: 44262 | H11: 4126 | I11: 700 | J11: 380 | K11: 3950 | Q11: =+SUM(E11:P11) -> 54722.78 | R11: =Q11/Q12 -> 0.781754 | S11: 0
D12: Budget | E12: 2500 | F12: 8000 | G12: 8000 | H12: 5000 | I12: 8000 | J12: 2000 | K12: 2000 | L12: 7000 | M12: 8000 | N12: 5000 | O12: 8000 | P12: 6500 | Q12: =SUM(E12:P12) -> 70000 | S12: =Q12/$Q$273 -> 0.0043745899
A13: Ann | B13: C-Anchored | C13: Edge Early Learning | D13: Actual | E13: 10031.03 | F13: 55953.408 | Q13: =+SUM(E13:P13) -> 65984.438 | R13: =Q13/Q14 -> 1.0997406 | S13: 0
D14: Budget | E14: 20000 | F14: 20000 | G14: 20000 | Q14: =SUM(E14:P14) -> 60000 | S14: =Q14/$Q$273 -> 0.0037496485
A15: Ann | B15: C-Anchored | C15: EG Australia | D15: Actual | E15: 7328.96 | F15: 3975.5527 | G15: 1436.6626 | H15: 8176.3572 | I15: 7295.2354 | J15: 4165.96 | K15: 7468.36 | Q15: =+SUM(E15:P15) -> 39847.088 | R15: =Q15/Q16 -> 0.33205907 | S15: 0
D16: Budget | E16: 10000 | F16: 10000 | G16: 10000 | H16: 10000 | I16: 10000 | J16: 10000 | K16: 10000 | L16: 10000 | M16: 10000 | N16: 10000 | O16: 10000 | P16: 10000 | Q16: =SUM(E16:P16) -> 120000 | S16: =Q16/$Q$273 -> 0.0074992969
A17: Ann | B17: C-Anchored | C17: DEICORP | D17: Actual | F17: 8103.5 | G17: 7506.65 | H17: 8037.4 | I17: 3657 | K17: 375 | Q17: =+SUM(E17:P17) -> 27679.55 | R17: =Q17/Q18 -> 0.36906067 | S17: #REF!
D18: Budget | E18: 5000 | F18: 5500 | G18: 5000 | H18: 4000 | I18: 5500 | J18: 3000 | K18: 8000 | L18: 2000 | M18: 5000 | N18: 7000 | O18: 15000 | P18: 10000 | Q18: =SUM(E18:P18) -> 75000 | S18: =Q18/#REF! -> #REF!
A19: Ann | B19: C-Anchored | C19: SMARTWAYS | D19: Actual | E19: 10921.75 | F19: 4290.05 | G19: 11387.15 | H19: 24688.9 | I19: 2981.8 | J19: 1304.83 | K19: 8721.8 | Q19: =+SUM(E19:P19) -> 64296.28 | R19: =Q19/Q20 -> 0.42721781 | S19: 0
D20: Budget | E20: 12500 | F20: 12500 | G20: 12500 | H20: 12500 | I20: 12500 | J20: 12500 | K20: 12500 | L20: 12500 | M20: 12500 | N20: 12500 | O20: 13000 | P20: 12500 | Q20: =SUM(E20:P20) -> 150500 | S20: =Q20/#REF! -> #REF!
A21: Ann | B21: C-Anchored | C21: Universal Kingdom of God | D21: Actual | Q21: =+SUM(E21:P21) -> 0 | R21: =Q21/Q22 -> 0 | S21: 0
D22: Budget | L22: 35000 | M22: 15000 | Q22: =SUM(E22:P22) -> 50000 | S22: =Q22/#REF! -> #REF!
A23: Ann | B23: C-Anchored | C23: Hall and Prior | D23: Actual | E23: 12661.63 | F23: 7797.22 | G23: 16019.05 | H23: 6941.28 | I23: 8709.1328 | J23: 4054.35 | K23: 10397.2 | Q23: =+SUM(E23:P23) -> 66579.863 | R23: =Q23/Q24 -> 1.1096644 | S23: 0
D24: Budget | E24: 5000 | F24: 5500 | G24: 5000 | H24: 3500 | I24: 4000 | J24: 3500 | K24: 5500 | L24: 4000 | M24: 7500 | N24: 5500 | O24: 5500 | P24: 5500 | Q24: =SUM(E24:P24) -> 60000 | S24: =Q24/$Q$273 -> 0.0037496485
A25: Ann | B25: C-Anchored | C25: HARDI AGED CARE | D25: Actual | E25: 7674.8 | F25: 10950.26 | G25: 5299.2692 | H25: 3850.5 | I25: 4922.0454 | J25: 3092.5 | K25: 5517 | Q25: =+SUM(E25:P25) -> 41306.375 | R25: =Q25/Q26 -> 0.68843958 | S25: 0
D26: Budget | E26: 5500 | F26: 5500 | G26: 4500 | H26: 5500 | I26: 5500 | J26: 3000 | K26: 3500 | L26: 5500 | M26: 5500 | N26: 5500 | O26: 5000 | P26: 5500 | Q26: =SUM(E26:P26) -> 60000 | S26: =Q26/$Q$273 -> 0.0037496485
A27: Ann | B27: C-Anchored | C27: RSL LIFECARE | D27: Actual | E27: 314 | G27: 330 | H27: 490 | I27: 1230 | J27: 1190 | K27: 400 | Q27: =+SUM(E27:P27) -> 3954 | R27: =Q27/Q28 -> 0.07908 | S27: 0
D28: Budget | E28: 6000 | F28: 6000 | G28: 6000 | H28: 3000 | I28: 3000 | J28: 3000 | K28: 4000 | L28: 3000 | M28: 3000 | N28: 3000 | O28: 5000 | P28: 5000 | Q28: =SUM(E28:P28) -> 50000 | S28: =Q28/$Q$273 -> 0.0031247071
A29: Ann | B29: C-Anchored | C29: MYCAR | D29: Actual | E29: 6185.5 | F29: 6568.12 | G29: 1233 | H29: 10321.5 | I29: 883.5 | J29: 21941.95 | K29: 3104 | Q29: =+SUM(E29:P29) -> 50237.57 | R29: =Q29/Q30 -> 0.71767957 | S29: 0
D30: Budget | E30: 4000 | F30: 4000 | G30: 4500 | H30: 5500 | I30: 15000 | J30: 4500 | K30: 2500 | L30: 4000 | M30: 15000 | N30: 5500 | O30: 2500 | P30: 3000 | Q30: =SUM(E30:P30) -> 70000 | S30: =Q30/$Q$273 -> 0.0043745899
A31: Ann | B31: C-Anchored | C31: MYCAR - ALSCO | D31: Actual | F31: 242.5 | Q31: =+SUM(E31:P31) -> 242.5 | R31: =Q31/Q32 -> 0.00080833333 | S31: 0
D32: Budget | O32: 300000 | Q32: =SUM(E32:P32) -> 300000 | S32: =Q32/$Q$273 -> 0.018748242
A33: Ann | B33: C-Anchored | C33: SYDNEY CRICKET & SPORTS GRD TR | D33: Actual | E33: 6727 | G33: 1376 | H33: 10620 | J33: 664 | K33: 4390 | Q33: =+SUM(E33:P33) -> 23777 | R33: =Q33/Q34 -> 0.21615455 | S33: 0
D34: Budget | E34: 25000 | F34: 25000 | G34: 20000 | H34: 10000 | K34: 20000 | P34: 10000 | Q34: =SUM(E34:P34) -> 110000 | S34: =Q34/$Q$273 -> 0.0068743555
A35: Ann | B35: C-Anchored | C35: Whiddon | D35: Actual | E35: 13608 | F35: 8708.08 | G35: 40710.54 | H35: 11881.35 | I35: 13751.909 | J35: 5429.09 | K35: 7206 | Q35: =+SUM(E35:P35) -> 101294.97 | R35: =Q35/Q36 -> 0.3376499 | S35: 0
D36: Budget | E36: 17000 | F36: 17000 | G36: 26600 | H36: 26600 | I36: 26600 | J36: 26600 | K36: 26600 | L36: 26600 | M36: 26600 | N36: 26600 | O36: 26600 | P36: 26600 | Q36: =SUM(E36:P36) -> 300000 | S36: =Q36/$Q$273 -> 0.018748242
A37: Ann | B37: C-Anchored | C37: Woolworths Metro | D37: Actual | E37: 8256.54 | F37: 9453.9 | G37: 7183 | H37: 11499.56 | I37: 8471.2744 | J37: 10013.42 | K37: 7217.45 | Q37: =+SUM(E37:P37) -> 62095.144 | R37: =Q37/Q38 -> 0.62095144 | S37: 0
D38: Budget | E38: 8500 | F38: 8500 | G38: 8500 | H38: 8500 | I38: 8500 | J38: 8500 | K38: 8000 | L38: 8000 | M38: 8500 | N38: 8500 | O38: 8000 | P38: 8000 | Q38: =SUM(E38:P38) -> 100000 | S38: =Q38/$Q$273 -> 0.0062494141
A39: Ann | B39: C-Anchored | C39: WOOLWORTHS - ALSCO | D39: Actual | E39: 206250 | F39: 165000 | Q39: =+SUM(E39:P39) -> 371250 | R39: =Q39/Q40 -> 0.80706522 | S39: 0
D40: Budget | E40: 210000 | G40: 165000 | N40: 85000 | Q40: =SUM(E40:P40) -> 460000 | S40: =Q40/$Q$273 -> 0.028747305
...

Sheet Q1 ONLY
A1: Sales Budget Vs Actual Invoiced- 1st July 2025 to 30 September 2025 - Q1 | H1: Annual | J1: % Of Sales
A2: Account Manager | B2: Non-Report | C2: Customer Name | E2: 45839 | F2: 45870 | G2: 45901 | H2: Total | I2: % to Budget
A3: Ann | B3: C-Anchored | C3: WINNING APPLIANCES | D3: Actual | E3: 770 | F3: 7770.75 | G3: 5529.97 | H3: =+SUM(E3:G3) -> 14070.72 | I3: =H3/H4 -> 1.5989455 | J3: 0
D4: Budget | E4: 3000 | F4: 4200 | G4: 1600 | H4: =SUM(E4:G4) -> 8800 | J4: =H4/$H$230 -> 0.0019731389
A5: Ann | B5: C-Anchored | C5: HARVEY NORMAN | D5: Actual | E5: 179440.36 | F5: 138218.8 | G5: 37125.06 | H5: =+SUM(E5:G5) -> 354784.22 | I5: =H5/H6 -> 1.2670865 | J5: 0
D6: Budget | E6: 105000 | F6: 100000 | G6: 75000 | H6: =SUM(E6:G6) -> 280000 | J6: =H6/$H$230 -> 0.062781691
A7: Ann | B7: C-Anchored | C7: HARVEY NORMAN NZ | D7: Actual | F7: 7973.4671 | G7: 154525.83 | H7: =+SUM(E7:G7) -> 162499.29 | I7: =H7/H8 -> 0.73863315 | J7: 0
D8: Budget | G8: 220000 | H8: =SUM(E8:G8) -> 220000 | J8: =H8/$H$230 -> 0.049328471
A9: Ann | B9: C-Anchored | C9: Aus Nursing Home (NHF) | D9: Actual | E9: 2856 | F9: 3702 | G9: 9691 | H9: =+SUM(E9:G9) -> 16249 | I9: =H9/H10 -> 1.1606429 | J9: 0
D10: Budget | E10: 4000 | F10: 5000 | G10: 5000 | H10: =SUM(E10:G10) -> 14000 | J10: =H10/$H$230 -> 0.0031390845
A11: Ann | B11: C-Anchored | C11: AUSTRALIAN MILITARY BANK | D11: Actual | E11: 2144 | F11: 8159.5 | G11: 4008 | H11: =+SUM(E11:G11) -> 14311.5 | I11: =H11/H12 -> 1.5064737 | J11: 0
D12: Budget | E12: 4000 | F12: 4000 | G12: 1500 | H12: =SUM(E12:G12) -> 9500 | J12: =H12/$H$230 -> 0.0021300931
A13: Ann | B13: C-Anchored | C13: CORNERSTONE HEALTH | D13: Actual | E13: 5435.32 | F13: 7118.27 | G13: 10258.05 | H13: =+SUM(E13:G13) -> 22811.64 | I13: =H13/H14 -> 1.2330616 | J13: 0
D14: Budget | E14: 6000 | F14: 6000 | G14: 6500 | H14: =SUM(E14:G14) -> 18500 | J14: =H14/$H$230 -> 0.004148076
A15: Ann | B15: C-Anchored | C15: Dooleys | D15: Actual | E15: 1304.78 | G15: 44262 | H15: =+SUM(E15:G15) -> 45566.78 | I15: =H15/H16 -> 2.4630692 | J15: 0
D16: Budget | E16: 2500 | F16: 8000 | G16: 8000 | H16: =SUM(E16:G16) -> 18500 | J16: =H16/$H$230 -> 0.004148076
A17: Ann | B17: C-Anchored | C17: Edge Early Learning | D17: Actual | E17: 10031.03 | F17: 55953.408 | H17: =+SUM(E17:G17) -> 65984.438 | I17: =H17/H18 -> 1.0997406 | J17: 0
D18: Budget | E18: 20000 | F18: 20000 | G18: 20000 | H18: =SUM(E18:G18) -> 60000 | J18: =H18/$H$230 -> 0.013453219
A19: Ann | B19: C-Anchored | C19: EG Australia | D19: Actual | E19: 7328.96 | F19: 3975.5527 | G19: 1436.6626 | H19: =+SUM(E19:G19) -> 12741.175 | I19: =H19/H20 -> 0.42470584 | J19: 0
D20: Budget | E20: 10000 | F20: 10000 | G20: 10000 | H20: =SUM(E20:G20) -> 30000 | J20: =H20/$H$230 -> 0.0067266097
A21: Ann | B21: C-Anchored | C21: Hall and Prior | D21: Actual | E21: 12661.63 | F21: 7797.22 | G21: 16019.05 | H21: =+SUM(E21:G21) -> 36477.9 | I21: =H21/H22 -> 2.3534129 | J21: 0
D22: Budget | E22: 5000 | F22: 5500 | G22: 5000 | H22: =SUM(E22:G22) -> 15500 | J22: =H22/$H$230 -> 0.003475415
A23: Ann | B23: C-Anchored | C23: HARDI AGED CARE | D23: Actual | E23: 7674.8 | F23: 10950.26 | G23: 5299.2692 | H23: =+SUM(E23:G23) -> 23924.329 | I23: =H23/H24 -> 1.5435051 | J23: 0
D24: Budget | E24: 5500 | F24: 5500 | G24: 4500 | H24: =SUM(E24:G24) -> 15500 | J24: =H24/$H$230 -> 0.003475415
A25: Ann | B25: C-Anchored | C25: RSL LIFECARE | D25: Actual | E25: 314 | G25: 330 | H25: =+SUM(E25:G25) -> 644 | I25: =H25/H26 -> 0.035777778 | J25: 0
D26: Budget | E26: 6000 | F26: 6000 | G26: 6000 | H26: =SUM(E26:G26) -> 18000 | J26: =H26/$H$230 -> 0.0040359658
A27: Ann | B27: C-Anchored | C27: MYCAR | D27: Actual | E27: 6185.5 | F27: 6568.12 | G27: 1233 | H27: =+SUM(E27:G27) -> 13986.62 | I27: =H27/H28 -> 1.1189296 | J27: 0
D28: Budget | E28: 4000 | F28: 4000 | G28: 4500 | H28: =SUM(E28:G28) -> 12500 | J28: =H28/$H$230 -> 0.0028027541
A29: Ann | B29: C-Anchored | C29: MYCAR - ALSCO | D29: Actual | F29: 242.5 | H29: =+SUM(E29:G29) -> 242.5 | I29: =H29/H30 -> #DIV/0! | J29: 0
D30: Budget | H30: =SUM(E30:G30) -> 0 | J30: =H30/$H$230 -> 0
A31: Ann | B31: C-Anchored | C31: SYDNEY CRICKET & SPORTS GRD TR | D31: Actual | E31: 6727 | G31: 1376 | H31: =+SUM(E31:G31) -> 8103 | I31: =H31/H32 -> 0.11575714 | J31: 0
D32: Budget | E32: 25000 | F32: 25000 | G32: 20000 | H32: =SUM(E32:G32) -> 70000 | J32: =H32/$H$230 -> 0.015695423
A33: Ann | B33: C-Anchored | C33: Whiddon | D33: Actual | E33: 13608 | F33: 8708.08 | G33: 40710.54 | H33: =+SUM(E33:G33) -> 63026.62 | I33: =H33/H34 -> 1.0400432 | J33: 0
D34: Budget | E34: 17000 | F34: 17000 | G34: 26600 | H34: =SUM(E34:G34) -> 60600 | J34: =H34/$H$230 -> 0.013587752
A35: Ann | B35: C-Anchored | C35: WOOLWORTHS - METRO | D35: Actual | E35: 8256.54 | F35: 9453.9 | G35: 7183 | H35: =+SUM(E35:G35) -> 24893.44 | I35: =H35/H36 -> 0.97621333 | J35: 0
D36: Budget | E36: 8500 | F36: 8500 | G36: 8500 | H36: =SUM(E36:G36) -> 25500 | J36: =H36/$H$230 -> 0.0057176183
A37: Ann | B37: C-Anchored | C37: WOOLWORTHS - ALSCO | D37: Actual | E37: 206250 | F37: 165000 | H37: =+SUM(E37:G37) -> 371250 | I37: =H37/H38 -> 0.99 | J37: 0
D38: Budget | E38: 210000 | G38: 165000 | H38: =SUM(E38:G38) -> 375000 | J38: =H38/$H$230 -> 0.084082622
A39: Ann | B39: C-Anchored | C39: Fantastic Furniture | D39: Actual | E39: 5868 | F39: 26762 | G39: 12594 | H39: =+SUM(E39:G39) -> 45224 | I39: =H39/H40 -> 1.7393846 | J39: 0
D40: Budget | E40: 10000 | F40: 10000 | G40: 6000 | H40: =SUM(E40:G40) -> 26000 | J40: =H40/$H$230 -> 0.0058297284
...

Sheet Working
A1: Customer Group | B1: Amount
A2: Row Labels | B2: Sum of SoldValue
A3: AFTERCARE/STRIDE | B3: 65
A4: Anytime Fitness | B4: 8953.36
A5: Apiam Animal Health | B5: 350
A6: ARCARE | B6: 17993
A7: Aus Nursing Home (NHF) | B7: 345
A8: AUSREO | B8: 2690.5
A9: AUSTRALIAN MILITARY BANK | B9: 1218
A10: Aveo Retirement Villages | B10: 3162.5
A11: BAPCOR | B11: 1091.5
A12: BENETAS | B12: 10247
A13: BIG RIVER GROUP | B13: 10202.5
A14: Canterbury League Club | B14: 1462
... A86: (blank) | B86: 17619.6
